Workbook
Name avg_equity: Ratios!$B$45
Name avg_total_assets: Ratios!$B$46
Name avg_total_cap: Ratios!$B$47
Name currentYear_AR: Ratios!$B$36
Name currentYear_assets: Ratios!$B$38
Name currentYear_CA: Ratios!$B$33
Name currentYear_cash: Ratios!$B$32
Name currentYear_CL: Ratios!$B$34
Name currentYear_equity: Ratios!$B$31
Name currentYear_inv: Ratios!$B$35
Name currentYear_liab: Ratios!$B$39
Name currentYear_lt_debt: Ratios!$B$37
Name currentYear_mkt_sec: Ratios!$B$42
Name currentYear_nwc: Ratios!$B$40
Name currentYear_total_cap: Ratios!$B$41
Name INC_after_tax_op: Ratios!$B$24
Name INC_daily_sales: Ratios!$B$26
Name INC_depr: Ratios!$B$27
Name INC_ebit: Ratios!$B$23
Name INC_ebitda: Ratios!$B$29
Name INC_interest: Ratios!$B$28
Name INC_net: Ratios!$B$22
Name INC_revenue: Ratios!$B$25
Name market_cap: Ratios!$B$9
Name market_share_price: Ratios!$B$7
Name market_shares_out: Ratios!$B$8
Name market_wacc: Ratios!$B$10
Name startYear_assets_total: Ratios!$B$17
Name startYear_equity: Ratios!$B$14
Name startYear_inventories: Ratios!$B$15
Name startYear_lt_debt: Ratios!$B$18
Name startYear_receivables: Ratios!$B$16
Name startYear_total_cap: Ratios!$B$19
Name tax_rate: Ratios!$B$11

Sheet Income Statement
A1: Apple Inc. — Consolidated Income Statement
A2: ($ in millions, except per share)
B4: FY2024 | C4: FY2023
A5: Net sales | B5: 391035 | C5: 383285
A6: Cost of sales | B6: 210352 | C6: 214137
A7: Gross margin | B7: =B5-B6 -> 180683 | C7: =C5-C6 -> 169148
A9: Operating expenses:
A10: Research and development | B10: 31370 | C10: 29915
A11: Selling, general and administrative | B11: 26097 | C11: 24932
A12: Total operating expenses | B12: =B10+B11 -> 57467 | C12: =C10+C11 -> 54847
A14: Operating income (EBIT) | B14: =B7-B12 -> 123216 | C14: =C7-C12 -> 114301
A15: Depreciation and amortization | B15: 11445 | C15: 11519
A16: EBITDA | B16: =B14+B15 -> 134661 | C16: =C14+C15 -> 125820
A18: Other income/(expense), net | B18: 269 | C18: -565
A19: Interest expense (estimated) | B19: 3600 | C19: 3933
A20: Income before taxes | B20: =B14+B18 -> 123485 | C20: =C14+C18 -> 113736
A21: Provision for income taxes | B21: 29749 | C21: 16741
A22: Net income | B22: =B20-B21 -> 93736 | C22: =C20-C21 -> 96995
A24: Effective tax rate | B24: =B21/B20 -> 0.24091185 | C24: =C21/C20 -> 0.14719174

Sheet Balance Sheet
A1: Apple Inc. — Consolidated Balance Sheets
A2: ($ in millions)
B3: Sep 28, 2024 | C3: Sep 30, 2023
A4: Current assets:
A5: Cash and cash equivalents | B5: 29943 | C5: 29965
A6: Marketable securities | B6: 35228 | C6: 31590
A7: Accounts receivable, net | B7: 33410 | C7: 29508
A8: Vendor non-trade receivables | B8: 32833 | C8: 31477
A9: Inventories | B9: 7286 | C9: 6331
A10: Other current assets | B10: 14287 | C10: 14695
A11: Total current assets | B11: 152987 | C11: 143566
A13: Non-current assets:
A14: Marketable securities | B14: 91479 | C14: 100544
A15: Property, plant and equipment, net | B15: 45680 | C15: 43715
A16: Other non-current assets | B16: 74834 | C16: 64758
A17: Total non-current assets | B17: 211993 | C17: 209017
A18: Total assets | B18: 364980 | C18: 352583
A20: Current liabilities:
A21: Accounts payable | B21: 68960 | C21: 62611
A22: Other current liabilities | B22: 78304 | C22: 58829
A23: Deferred revenue | B23: 8249 | C23: 8061
A24: Commercial paper | B24: 9967 | C24: 5985
A25: Term debt (current) | B25: 10912 | C25: 9822
A26: Total current liabilities | B26: 176392 | C26: 145308
A28: Non-current liabilities:
A29: Term debt (non-current) | B29: 85750 | C29: 95281
A30: Other non-current liabilities | B30: 45888 | C30: 49848
A31: Total non-current liabilities | B31: 131638 | C31: 145129
A32: Total liabilities | B32: 308030 | C32: 290437
A34: Shareholders' equity:
A35: Common stock and APIC | B35: 83276 | C35: 73812
A36: Accumulated deficit | B36: -19154 | C36: -214
A37: AOCI | B37: -7172 | C37: -11452
A38: Total shareholders' equity | B38: 56950 | C38: 62146
A39: Total liabilities and equity | B39: 364980 | C39: 352583

Sheet Cash Flow
A1: Apple Inc. — Cash Flow Statement
A2: ($ in millions)
B3: FY2024 | C3: FY2023
A4: Operating activities:
A5: Net income | B5: 93736 | C5: 96995
A6: Depreciation and amortization | B6: 11445 | C6: 11519
A7: Share-based compensation | B7: 11688 | C7: 10833
A8: Other | B8: -2266 | C8: -2227
A9: Changes in working capital:
A10: Accounts receivable | B10: -3788 | C10: -1688
A11: Vendor non-trade receivables | B11: -1356 | C11: 1271
A12: Inventories | B12: -1046 | C12: -1618
A13: Other assets | B13: -11731 | C13: -5684
A14: Accounts payable | B14: 6020 | C14: -1889
A15: Other liabilities | B15: 15552 | C15: 3031
A16: Cash from operating activities | B16: 118254 | C16: 110543
A18: Investing activities:
A19: Purchases of marketable securities | B19: -48656 | C19: -29513
A20: Maturities of marketable securities | B20: 51211 | C20: 39686
A21: Sales of marketable securities | B21: 11135 | C21: 5828
A22: Purchases of PP&E | B22: -9447 | C22: -10959
A23: Other | B23: -1308 | C23: -1337
A24: Cash from investing activities | B24: 2935 | C24: 3705
A26: Financing activities:
A27: Taxes - net share settlement | B27: -5441 | C27: -5431
A28: Dividends | B28: -15234 | C28: -15025
A29: Share repurchases | B29: -94949 | C29: -77550
A30: Term debt issuance | B30: 0 | C30: 5228
A31: Term debt repayments | B31: -9958 | C31: -11151
A32: Commercial paper, net | B32: 3960 | C32: -3978
A33: Other | B33: -361 | C33: -581
A34: Cash from financing activities | B34: -121983 | C34: -108488

Sheet Ratios
A1: Apple Inc. — Financial Ratio Analysis
A2: Current Year: FY2024 (ended Sep 28, 2024)
A4: INPUTS
A5: Item | B5: Value ($M) | C5: Named Range
A6: — Market / Analyst Inputs —
A7: Share price ($) | B7: 258.9 | C7: market_share_price
A8: Shares outstanding (thousands) | B8: 15116786 | C8: market_shares_out
A9: Market capitalization | B9: =B7*B8/1000 -> 3913735.9 | C9: market_cap
A10: Cost of capital (WACC) | B10: 0.1 | C10: market_wacc
A11: Effective tax rate | B11: ='Income Statement'!B24 -> 0.24091185 | C11: tax_rate
A13: — Start-of-Year (Sep 30, 2023) —
A14: Equity (start) | B14: 62146 | C14: startYear_equity
A15: Inventories (start) | B15: 6331 | C15: startYear_inventories
A16: Accounts receivable (start) | B16: 29508 | C16: startYear_receivables
A17: Total assets (start) | B17: 352583 | C17: startYear_assets_total
A18: Long-term debt (start) | B18: 95281 | C18: startYear_lt_debt
A19: Total capitalization (start) | B19: =B18+B14 -> 157427 | C19: startYear_total_cap
A21: — Current-Year (Sep 28, 2024) —
A22: Net income | B22: ='Income Statement'!B22 -> 93736 | C22: INC_net
A23: Operating income (EBIT) | B23: ='Income Statement'!B14 -> 123216 | C23: INC_ebit
A24: After-tax operating income | B24: =B23*(1-B11) -> 93531.805 | C24: INC_after_tax_op
A25: Revenue | B25: ='Income Statement'!B5 -> 391035 | C25: INC_revenue
A26: Daily sales | B26: =B25/365 -> 1071.3288 | C26: INC_daily_sales
A27: Depreciation & amortization | B27: ='Income Statement'!B15 -> 11445 | C27: INC_depr
A28: Interest expense | B28: ='Income Statement'!B19 -> 3600 | C28: INC_interest
A29: EBITDA | B29: ='Income Statement'!B16 -> 134661 | C29: INC_ebitda
A31: Book equity (current) | B31: ='Balance Sheet'!B38 -> 56950 | C31: currentYear_equity
A32: Cash | B32: ='Balance Sheet'!B5 -> 29943 | C32: currentYear_cash
A33: Current assets | B33: ='Balance Sheet'!B11 -> 152987 | C33: currentYear_CA
A34: Current liabilities | B34: ='Balance Sheet'!B26 -> 176392 | C34: currentYear_CL
A35: Inventories (current) | B35: ='Balance Sheet'!B9 -> 7286 | C35: currentYear_inv
A36: AR (current) | B36: ='Balance Sheet'!B7 -> 33410 | C36: currentYear_AR
A37: Long-term debt | B37: ='Balance Sheet'!B29 -> 85750 | C37: currentYear_lt_debt
A38: Total assets | B38: ='Balance Sheet'!B18 -> 364980 | C38: currentYear_assets
A39: Total liabilities | B39: ='Balance Sheet'!B32 -> 308030 | C39: currentYear_liab
A40: NWC | B40: =B33-B34 -> -23405 | C40: currentYear_nwc
A41: Total capitalization | B41: =B37+B31 -> 142700 | C41: currentYear_total_cap
A42: Mkt securities (current) | B42: ='Balance Sheet'!B6 -> 35228 | C42: currentYear_mkt_sec
A44: — Average Items —
A45: Average equity | B45: =(B14+B31)/2 -> 59548 | C45: avg_equity
...

Sheet Notes
A1: Notes, Assumptions & Data Sources
A3: DATA SOURCES
A4: All financial data: Apple Inc. Form 10-K, fiscal year ended Sep 28, 2024 (Filed Nov 1, 2024).
A5: SEC EDGAR CIK: 0000320193
A6: Prior-year comparatives: Sep 30, 2023 balance sheet from same 10-K filing.
A7: Share price (~$258.90): approximate close as of April 2026 (Yahoo Finance).
A9: KEY ASSUMPTIONS
A10: Interest expense ($3,600M FY2024): estimated from note disclosures. Apple's income statement
A11: reports 'Other income/(expense), net' as a single line. FY2023 10-K disclosed interest expense
A12: of $3,933M. FY2024 estimate reflects lower outstanding term debt balance.
A13: WACC (10%): placeholder assumption. A full WACC would incorporate Apple's equity beta,
A14: the risk-free rate, equity risk premium, and after-tax cost of debt.
... A33: Cost of sales used for inventory turnover (from income statement row 6).
